INFO 2025-05-17 21:42:34,166 autoreload 11233 140692988442432 Watching for file changes with StatReloader
INFO 2025-05-17 21:42:57,942 autoreload 11399 140259243820864 Watching for file changes with StatReloader
WARNING 2025-05-17 22:00:35,819 log 11399 140259183556288 Not Found: /
WARNING 2025-05-17 22:00:35,820 basehttp 11399 140259183556288 "GET / HTTP/1.1" 404 2483
WARNING 2025-05-17 22:00:36,246 log 11399 140259183556288 Not Found: /favicon.ico
INFO 2025-05-17 22:05:14,903 autoreload 11399 140259243820864 /home/maxwell/Videos/vlatestportfoliowebsite/backend/django_portfolio/django_portfolio/urls.py changed, reloading.
INFO 2025-05-17 22:05:15,802 autoreload 14304 140313212647232 Watching for file changes with StatReloader
ERROR 2025-05-17 22:33:38,932 log 15998 140667560916672 Internal Server Error: /api/projects/
Traceback (most recent call last):
  File "/home/maxwell/Videos/vlatestportfoliowebsite/.venv/lib/python3.13/site-packages/django/db/backends/utils.py", line 105, in _execute
    return self.cursor.execute(sql, params)
           ~~~~~~~~~~~~~~~~~~~^^^^^^^^^^^^^
  File "/home/maxwell/Videos/vlatestportfoliowebsite/.venv/lib/python3.13/site-packages/django/db/backends/sqlite3/base.py", line 360, in execute
    return super().execute(query, params)
           ~~~~~~~~~~~~~~~^^^^^^^^^^^^^^^
sqlite3.OperationalError: no such table: portfolio_project

The above exception was the direct cause of the following exception:

Traceback (most recent call last):
  File "/home/maxwell/Videos/vlatestportfoliowebsite/.venv/lib/python3.13/site-packages/asgiref/sync.py", line 518, in thread_handler
    raise exc_info[1]
  File "/home/maxwell/Videos/vlatestportfoliowebsite/.venv/lib/python3.13/site-packages/django/core/handlers/exception.py", line 42, in inner
    response = await get_response(request)
               ^^^^^^^^^^^^^^^^^^^^^^^^^^^
  File "/home/maxwell/Videos/vlatestportfoliowebsite/.venv/lib/python3.13/site-packages/asgiref/sync.py", line 518, in thread_handler
    raise exc_info[1]
  File "/home/maxwell/Videos/vlatestportfoliowebsite/.venv/lib/python3.13/site-packages/django/core/handlers/base.py", line 253, in _get_response_async
    response = await wrapped_callback(
               ^^^^^^^^^^^^^^^^^^^^^^^
        request, *callback_args, **callback_kwargs
        ^^^^^^^^^^^^^^^^^^^^^^^^^^^^^^^^^^^^^^^^^^
    )
    ^
  File "/home/maxwell/Videos/vlatestportfoliowebsite/.venv/lib/python3.13/site-packages/asgiref/sync.py", line 468, in __call__
    ret = await asyncio.shield(exec_coro)
          ^^^^^^^^^^^^^^^^^^^^^^^^^^^^^^^
  File "/usr/local/lib/python3.13/concurrent/futures/thread.py", line 59, in run
    result = self.fn(*self.args, **self.kwargs)
  File "/home/maxwell/Videos/vlatestportfoliowebsite/.venv/lib/python3.13/site-packages/asgiref/sync.py", line 522, in thread_handler
    return func(*args, **kwargs)
  File "/home/maxwell/Videos/vlatestportfoliowebsite/.venv/lib/python3.13/site-packages/django/views/decorators/csrf.py", line 65, in _view_wrapper
    return view_func(request, *args, **kwargs)
  File "/home/maxwell/Videos/vlatestportfoliowebsite/.venv/lib/python3.13/site-packages/rest_framework/viewsets.py", line 125, in view
    return self.dispatch(request, *args, **kwargs)
           ~~~~~~~~~~~~~^^^^^^^^^^^^^^^^^^^^^^^^^^
  File "/home/maxwell/Videos/vlatestportfoliowebsite/.venv/lib/python3.13/site-packages/rest_framework/views.py", line 515, in dispatch
    response = self.handle_exception(exc)
  File "/home/maxwell/Videos/vlatestportfoliowebsite/.venv/lib/python3.13/site-packages/rest_framework/views.py", line 475, in handle_exception
    self.raise_uncaught_exception(exc)
    ~~~~~~~~~~~~~~~~~~~~~~~~~~~~~^^^^^
  File "/home/maxwell/Videos/vlatestportfoliowebsite/.venv/lib/python3.13/site-packages/rest_framework/views.py", line 486, in raise_uncaught_exception
    raise exc
  File "/home/maxwell/Videos/vlatestportfoliowebsite/.venv/lib/python3.13/site-packages/rest_framework/views.py", line 512, in dispatch
    response = handler(request, *args, **kwargs)
  File "/home/maxwell/Videos/vlatestportfoliowebsite/backend/django_portfolio/portfolio/views.py", line 149, in list
    print(f"Found {queryset.count()} projects")
                   ~~~~~~~~~~~~~~^^
  File "/home/maxwell/Videos/vlatestportfoliowebsite/.venv/lib/python3.13/site-packages/django/db/models/query.py", line 604, in count
    return self.query.get_count(using=self.db)
           ~~~~~~~~~~~~~~~~~~~~^^^^^^^^^^^^^^^
  File "/home/maxwell/Videos/vlatestportfoliowebsite/.venv/lib/python3.13/site-packages/django/db/models/sql/query.py", line 644, in get_count
    return obj.get_aggregation(using, {"__count": Count("*")})["__count"]
           ~~~~~~~~~~~~~~~~~~~^^^^^^^^^^^^^^^^^^^^^^^^^^^^^^^^
  File "/home/maxwell/Videos/vlatestportfoliowebsite/.venv/lib/python3.13/site-packages/django/db/models/sql/query.py", line 626, in get_aggregation
    result = compiler.execute_sql(SINGLE)
  File "/home/maxwell/Videos/vlatestportfoliowebsite/.venv/lib/python3.13/site-packages/django/db/models/sql/compiler.py", line 1623, in execute_sql
    cursor.execute(sql, params)
    ~~~~~~~~~~~~~~^^^^^^^^^^^^^
  File "/home/maxwell/Videos/vlatestportfoliowebsite/.venv/lib/python3.13/site-packages/django/db/backends/utils.py", line 122, in execute
    return super().execute(sql, params)
           ~~~~~~~~~~~~~~~^^^^^^^^^^^^^
  File "/home/maxwell/Videos/vlatestportfoliowebsite/.venv/lib/python3.13/site-packages/django/db/backends/utils.py", line 79, in execute
    return self._execute_with_wrappers(
           ~~~~~~~~~~~~~~~~~~~~~~~~~~~^
        sql, params, many=False, executor=self._execute
        ^^^^^^^^^^^^^^^^^^^^^^^^^^^^^^^^^^^^^^^^^^^^^^^
    )
    ^
  File "/home/maxwell/Videos/vlatestportfoliowebsite/.venv/lib/python3.13/site-packages/django/db/backends/utils.py", line 92, in _execute_with_wrappers
    return executor(sql, params, many, context)
  File "/home/maxwell/Videos/vlatestportfoliowebsite/.venv/lib/python3.13/site-packages/django/db/backends/utils.py", line 100, in _execute
    with self.db.wrap_database_errors:
         ^^^^^^^^^^^^^^^^^^^^^^^^^^^^
  File "/home/maxwell/Videos/vlatestportfoliowebsite/.venv/lib/python3.13/site-packages/django/db/utils.py", line 91, in __exit__
    raise dj_exc_value.with_traceback(traceback) from exc_value
  File "/home/maxwell/Videos/vlatestportfoliowebsite/.venv/lib/python3.13/site-packages/django/db/backends/utils.py", line 105, in _execute
    return self.cursor.execute(sql, params)
           ~~~~~~~~~~~~~~~~~~~^^^^^^^^^^^^^
  File "/home/maxwell/Videos/vlatestportfoliowebsite/.venv/lib/python3.13/site-packages/django/db/backends/sqlite3/base.py", line 360, in execute
    return super().execute(query, params)
           ~~~~~~~~~~~~~~~^^^^^^^^^^^^^^^
django.db.utils.OperationalError: no such table: portfolio_project
ERROR 2025-05-17 22:33:38,939 log 15998 140667774453440 Internal Server Error: /api/projects/
Traceback (most recent call last):
  File "/home/maxwell/Videos/vlatestportfoliowebsite/.venv/lib/python3.13/site-packages/django/db/backends/utils.py", line 105, in _execute
    return self.cursor.execute(sql, params)
           ~~~~~~~~~~~~~~~~~~~^^^^^^^^^^^^^
  File "/home/maxwell/Videos/vlatestportfoliowebsite/.venv/lib/python3.13/site-packages/django/db/backends/sqlite3/base.py", line 360, in execute
    return super().execute(query, params)
           ~~~~~~~~~~~~~~~^^^^^^^^^^^^^^^
sqlite3.OperationalError: no such table: portfolio_project

The above exception was the direct cause of the following exception:

Traceback (most recent call last):
  File "/home/maxwell/Videos/vlatestportfoliowebsite/.venv/lib/python3.13/site-packages/asgiref/sync.py", line 518, in thread_handler
    raise exc_info[1]
  File "/home/maxwell/Videos/vlatestportfoliowebsite/.venv/lib/python3.13/site-packages/django/core/handlers/exception.py", line 42, in inner
    response = await get_response(request)
               ^^^^^^^^^^^^^^^^^^^^^^^^^^^
  File "/home/maxwell/Videos/vlatestportfoliowebsite/.venv/lib/python3.13/site-packages/asgiref/sync.py", line 518, in thread_handler
    raise exc_info[1]
  File "/home/maxwell/Videos/vlatestportfoliowebsite/.venv/lib/python3.13/site-packages/django/core/handlers/base.py", line 253, in _get_response_async
    response = await wrapped_callback(
               ^^^^^^^^^^^^^^^^^^^^^^^
        request, *callback_args, **callback_kwargs
        ^^^^^^^^^^^^^^^^^^^^^^^^^^^^^^^^^^^^^^^^^^
    )
    ^
  File "/home/maxwell/Videos/vlatestportfoliowebsite/.venv/lib/python3.13/site-packages/asgiref/sync.py", line 468, in __call__
    ret = await asyncio.shield(exec_coro)
          ^^^^^^^^^^^^^^^^^^^^^^^^^^^^^^^
  File "/usr/local/lib/python3.13/concurrent/futures/thread.py", line 59, in run
    result = self.fn(*self.args, **self.kwargs)
  File "/home/maxwell/Videos/vlatestportfoliowebsite/.venv/lib/python3.13/site-packages/asgiref/sync.py", line 522, in thread_handler
    return func(*args, **kwargs)
  File "/home/maxwell/Videos/vlatestportfoliowebsite/.venv/lib/python3.13/site-packages/django/views/decorators/csrf.py", line 65, in _view_wrapper
    return view_func(request, *args, **kwargs)
  File "/home/maxwell/Videos/vlatestportfoliowebsite/.venv/lib/python3.13/site-packages/rest_framework/viewsets.py", line 125, in view
    return self.dispatch(request, *args, **kwargs)
           ~~~~~~~~~~~~~^^^^^^^^^^^^^^^^^^^^^^^^^^
  File "/home/maxwell/Videos/vlatestportfoliowebsite/.venv/lib/python3.13/site-packages/rest_framework/views.py", line 515, in dispatch
    response = self.handle_exception(exc)
  File "/home/maxwell/Videos/vlatestportfoliowebsite/.venv/lib/python3.13/site-packages/rest_framework/views.py", line 475, in handle_exception
    self.raise_uncaught_exception(exc)
    ~~~~~~~~~~~~~~~~~~~~~~~~~~~~~^^^^^
  File "/home/maxwell/Videos/vlatestportfoliowebsite/.venv/lib/python3.13/site-packages/rest_framework/views.py", line 486, in raise_uncaught_exception
    raise exc
  File "/home/maxwell/Videos/vlatestportfoliowebsite/.venv/lib/python3.13/site-packages/rest_framework/views.py", line 512, in dispatch
    response = handler(request, *args, **kwargs)
  File "/home/maxwell/Videos/vlatestportfoliowebsite/backend/django_portfolio/portfolio/views.py", line 149, in list
    print(f"Found {queryset.count()} projects")
                   ~~~~~~~~~~~~~~^^
  File "/home/maxwell/Videos/vlatestportfoliowebsite/.venv/lib/python3.13/site-packages/django/db/models/query.py", line 604, in count
    return self.query.get_count(using=self.db)
           ~~~~~~~~~~~~~~~~~~~~^^^^^^^^^^^^^^^
  File "/home/maxwell/Videos/vlatestportfoliowebsite/.venv/lib/python3.13/site-packages/django/db/models/sql/query.py", line 644, in get_count
    return obj.get_aggregation(using, {"__count": Count("*")})["__count"]
           ~~~~~~~~~~~~~~~~~~~^^^^^^^^^^^^^^^^^^^^^^^^^^^^^^^^
  File "/home/maxwell/Videos/vlatestportfoliowebsite/.venv/lib/python3.13/site-packages/django/db/models/sql/query.py", line 626, in get_aggregation
    result = compiler.execute_sql(SINGLE)
  File "/home/maxwell/Videos/vlatestportfoliowebsite/.venv/lib/python3.13/site-packages/django/db/models/sql/compiler.py", line 1623, in execute_sql
    cursor.execute(sql, params)
    ~~~~~~~~~~~~~~^^^^^^^^^^^^^
  File "/home/maxwell/Videos/vlatestportfoliowebsite/.venv/lib/python3.13/site-packages/django/db/backends/utils.py", line 122, in execute
    return super().execute(sql, params)
           ~~~~~~~~~~~~~~~^^^^^^^^^^^^^
  File "/home/maxwell/Videos/vlatestportfoliowebsite/.venv/lib/python3.13/site-packages/django/db/backends/utils.py", line 79, in execute
    return self._execute_with_wrappers(
           ~~~~~~~~~~~~~~~~~~~~~~~~~~~^
        sql, params, many=False, executor=self._execute
        ^^^^^^^^^^^^^^^^^^^^^^^^^^^^^^^^^^^^^^^^^^^^^^^
    )
    ^
  File "/home/maxwell/Videos/vlatestportfoliowebsite/.venv/lib/python3.13/site-packages/django/db/backends/utils.py", line 92, in _execute_with_wrappers
    return executor(sql, params, many, context)
  File "/home/maxwell/Videos/vlatestportfoliowebsite/.venv/lib/python3.13/site-packages/django/db/backends/utils.py", line 100, in _execute
    with self.db.wrap_database_errors:
         ^^^^^^^^^^^^^^^^^^^^^^^^^^^^
  File "/home/maxwell/Videos/vlatestportfoliowebsite/.venv/lib/python3.13/site-packages/django/db/utils.py", line 91, in __exit__
    raise dj_exc_value.with_traceback(traceback) from exc_value
  File "/home/maxwell/Videos/vlatestportfoliowebsite/.venv/lib/python3.13/site-packages/django/db/backends/utils.py", line 105, in _execute
    return self.cursor.execute(sql, params)
           ~~~~~~~~~~~~~~~~~~~^^^^^^^^^^^^^
  File "/home/maxwell/Videos/vlatestportfoliowebsite/.venv/lib/python3.13/site-packages/django/db/backends/sqlite3/base.py", line 360, in execute
    return super().execute(query, params)
           ~~~~~~~~~~~~~~~^^^^^^^^^^^^^^^
django.db.utils.OperationalError: no such table: portfolio_project
ERROR 2025-05-17 22:34:48,109 log 16661 139807532512960 Internal Server Error: /api/projects/
Traceback (most recent call last):
  File "/home/maxwell/Videos/vlatestportfoliowebsite/.venv/lib/python3.13/site-packages/django/db/backends/utils.py", line 105, in _execute
    return self.cursor.execute(sql, params)
           ~~~~~~~~~~~~~~~~~~~^^^^^^^^^^^^^
  File "/home/maxwell/Videos/vlatestportfoliowebsite/.venv/lib/python3.13/site-packages/django/db/backends/sqlite3/base.py", line 360, in execute
    return super().execute(query, params)
           ~~~~~~~~~~~~~~~^^^^^^^^^^^^^^^
sqlite3.OperationalError: no such table: portfolio_project

The above exception was the direct cause of the following exception:

Traceback (most recent call last):
  File "/home/maxwell/Videos/vlatestportfoliowebsite/.venv/lib/python3.13/site-packages/asgiref/sync.py", line 518, in thread_handler
    raise exc_info[1]
  File "/home/maxwell/Videos/vlatestportfoliowebsite/.venv/lib/python3.13/site-packages/django/core/handlers/exception.py", line 42, in inner
    response = await get_response(request)
               ^^^^^^^^^^^^^^^^^^^^^^^^^^^
  File "/home/maxwell/Videos/vlatestportfoliowebsite/.venv/lib/python3.13/site-packages/asgiref/sync.py", line 518, in thread_handler
    raise exc_info[1]
  File "/home/maxwell/Videos/vlatestportfoliowebsite/.venv/lib/python3.13/site-packages/django/core/handlers/base.py", line 253, in _get_response_async
    response = await wrapped_callback(
               ^^^^^^^^^^^^^^^^^^^^^^^
        request, *callback_args, **callback_kwargs
        ^^^^^^^^^^^^^^^^^^^^^^^^^^^^^^^^^^^^^^^^^^
    )
    ^
  File "/home/maxwell/Videos/vlatestportfoliowebsite/.venv/lib/python3.13/site-packages/asgiref/sync.py", line 468, in __call__
    ret = await asyncio.shield(exec_coro)
          ^^^^^^^^^^^^^^^^^^^^^^^^^^^^^^^
  File "/usr/local/lib/python3.13/concurrent/futures/thread.py", line 59, in run
    result = self.fn(*self.args, **self.kwargs)
  File "/home/maxwell/Videos/vlatestportfoliowebsite/.venv/lib/python3.13/site-packages/asgiref/sync.py", line 522, in thread_handler
    return func(*args, **kwargs)
  File "/home/maxwell/Videos/vlatestportfoliowebsite/.venv/lib/python3.13/site-packages/django/views/decorators/csrf.py", line 65, in _view_wrapper
    return view_func(request, *args, **kwargs)
  File "/home/maxwell/Videos/vlatestportfoliowebsite/.venv/lib/python3.13/site-packages/rest_framework/viewsets.py", line 125, in view
    return self.dispatch(request, *args, **kwargs)
           ~~~~~~~~~~~~~^^^^^^^^^^^^^^^^^^^^^^^^^^
  File "/home/maxwell/Videos/vlatestportfoliowebsite/.venv/lib/python3.13/site-packages/rest_framework/views.py", line 515, in dispatch
    response = self.handle_exception(exc)
  File "/home/maxwell/Videos/vlatestportfoliowebsite/.venv/lib/python3.13/site-packages/rest_framework/views.py", line 475, in handle_exception
    self.raise_uncaught_exception(exc)
    ~~~~~~~~~~~~~~~~~~~~~~~~~~~~~^^^^^
  File "/home/maxwell/Videos/vlatestportfoliowebsite/.venv/lib/python3.13/site-packages/rest_framework/views.py", line 486, in raise_uncaught_exception
    raise exc
  File "/home/maxwell/Videos/vlatestportfoliowebsite/.venv/lib/python3.13/site-packages/rest_framework/views.py", line 512, in dispatch
    response = handler(request, *args, **kwargs)
  File "/home/maxwell/Videos/vlatestportfoliowebsite/backend/django_portfolio/portfolio/views.py", line 149, in list
    print(f"Found {queryset.count()} projects")
                   ~~~~~~~~~~~~~~^^
  File "/home/maxwell/Videos/vlatestportfoliowebsite/.venv/lib/python3.13/site-packages/django/db/models/query.py", line 604, in count
    return self.query.get_count(using=self.db)
           ~~~~~~~~~~~~~~~~~~~~^^^^^^^^^^^^^^^
  File "/home/maxwell/Videos/vlatestportfoliowebsite/.venv/lib/python3.13/site-packages/django/db/models/sql/query.py", line 644, in get_count
    return obj.get_aggregation(using, {"__count": Count("*")})["__count"]
           ~~~~~~~~~~~~~~~~~~~^^^^^^^^^^^^^^^^^^^^^^^^^^^^^^^^
  File "/home/maxwell/Videos/vlatestportfoliowebsite/.venv/lib/python3.13/site-packages/django/db/models/sql/query.py", line 626, in get_aggregation
    result = compiler.execute_sql(SINGLE)
  File "/home/maxwell/Videos/vlatestportfoliowebsite/.venv/lib/python3.13/site-packages/django/db/models/sql/compiler.py", line 1623, in execute_sql
    cursor.execute(sql, params)
    ~~~~~~~~~~~~~~^^^^^^^^^^^^^
  File "/home/maxwell/Videos/vlatestportfoliowebsite/.venv/lib/python3.13/site-packages/django/db/backends/utils.py", line 122, in execute
    return super().execute(sql, params)
           ~~~~~~~~~~~~~~~^^^^^^^^^^^^^
  File "/home/maxwell/Videos/vlatestportfoliowebsite/.venv/lib/python3.13/site-packages/django/db/backends/utils.py", line 79, in execute
    return self._execute_with_wrappers(
           ~~~~~~~~~~~~~~~~~~~~~~~~~~~^
        sql, params, many=False, executor=self._execute
        ^^^^^^^^^^^^^^^^^^^^^^^^^^^^^^^^^^^^^^^^^^^^^^^
    )
    ^
  File "/home/maxwell/Videos/vlatestportfoliowebsite/.venv/lib/python3.13/site-packages/django/db/backends/utils.py", line 92, in _execute_with_wrappers
    return executor(sql, params, many, context)
  File "/home/maxwell/Videos/vlatestportfoliowebsite/.venv/lib/python3.13/site-packages/django/db/backends/utils.py", line 100, in _execute
    with self.db.wrap_database_errors:
         ^^^^^^^^^^^^^^^^^^^^^^^^^^^^
  File "/home/maxwell/Videos/vlatestportfoliowebsite/.venv/lib/python3.13/site-packages/django/db/utils.py", line 91, in __exit__
    raise dj_exc_value.with_traceback(traceback) from exc_value
  File "/home/maxwell/Videos/vlatestportfoliowebsite/.venv/lib/python3.13/site-packages/django/db/backends/utils.py", line 105, in _execute
    return self.cursor.execute(sql, params)
           ~~~~~~~~~~~~~~~~~~~^^^^^^^^^^^^^
  File "/home/maxwell/Videos/vlatestportfoliowebsite/.venv/lib/python3.13/site-packages/django/db/backends/sqlite3/base.py", line 360, in execute
    return super().execute(query, params)
           ~~~~~~~~~~~~~~~^^^^^^^^^^^^^^^
django.db.utils.OperationalError: no such table: portfolio_project
WARNING 2025-05-17 22:36:16,576 log 16661 139807532512960 Bad Request: /api/projects/
ERROR 2025-05-18 07:55:24,799 log 3900 139732197570240 Internal Server Error: /api/projects/
Traceback (most recent call last):
  File "/home/maxwell/Videos/vlatestportfoliowebsite/.venv/lib/python3.13/site-packages/django/db/backends/utils.py", line 105, in _execute
    return self.cursor.execute(sql, params)
           ~~~~~~~~~~~~~~~~~~~^^^^^^^^^^^^^
  File "/home/maxwell/Videos/vlatestportfoliowebsite/.venv/lib/python3.13/site-packages/django/db/backends/sqlite3/base.py", line 360, in execute
    return super().execute(query, params)
           ~~~~~~~~~~~~~~~^^^^^^^^^^^^^^^
sqlite3.OperationalError: no such table: portfolio_project

The above exception was the direct cause of the following exception:

Traceback (most recent call last):
  File "/home/maxwell/Videos/vlatestportfoliowebsite/.venv/lib/python3.13/site-packages/asgiref/sync.py", line 518, in thread_handler
    raise exc_info[1]
  File "/home/maxwell/Videos/vlatestportfoliowebsite/.venv/lib/python3.13/site-packages/django/core/handlers/exception.py", line 42, in inner
    response = await get_response(request)
               ^^^^^^^^^^^^^^^^^^^^^^^^^^^
  File "/home/maxwell/Videos/vlatestportfoliowebsite/.venv/lib/python3.13/site-packages/asgiref/sync.py", line 518, in thread_handler
    raise exc_info[1]
  File "/home/maxwell/Videos/vlatestportfoliowebsite/.venv/lib/python3.13/site-packages/django/core/handlers/base.py", line 253, in _get_response_async
    response = await wrapped_callback(
               ^^^^^^^^^^^^^^^^^^^^^^^
        request, *callback_args, **callback_kwargs
        ^^^^^^^^^^^^^^^^^^^^^^^^^^^^^^^^^^^^^^^^^^
    )
    ^
  File "/home/maxwell/Videos/vlatestportfoliowebsite/.venv/lib/python3.13/site-packages/asgiref/sync.py", line 468, in __call__
    ret = await asyncio.shield(exec_coro)
          ^^^^^^^^^^^^^^^^^^^^^^^^^^^^^^^
  File "/usr/local/lib/python3.13/concurrent/futures/thread.py", line 59, in run
    result = self.fn(*self.args, **self.kwargs)
  File "/home/maxwell/Videos/vlatestportfoliowebsite/.venv/lib/python3.13/site-packages/asgiref/sync.py", line 522, in thread_handler
    return func(*args, **kwargs)
  File "/home/maxwell/Videos/vlatestportfoliowebsite/.venv/lib/python3.13/site-packages/django/views/decorators/csrf.py", line 65, in _view_wrapper
    return view_func(request, *args, **kwargs)
  File "/home/maxwell/Videos/vlatestportfoliowebsite/.venv/lib/python3.13/site-packages/rest_framework/viewsets.py", line 125, in view
    return self.dispatch(request, *args, **kwargs)
           ~~~~~~~~~~~~~^^^^^^^^^^^^^^^^^^^^^^^^^^
  File "/home/maxwell/Videos/vlatestportfoliowebsite/.venv/lib/python3.13/site-packages/rest_framework/views.py", line 515, in dispatch
    response = self.handle_exception(exc)
  File "/home/maxwell/Videos/vlatestportfoliowebsite/.venv/lib/python3.13/site-packages/rest_framework/views.py", line 475, in handle_exception
    self.raise_uncaught_exception(exc)
    ~~~~~~~~~~~~~~~~~~~~~~~~~~~~~^^^^^
  File "/home/maxwell/Videos/vlatestportfoliowebsite/.venv/lib/python3.13/site-packages/rest_framework/views.py", line 486, in raise_uncaught_exception
    raise exc
  File "/home/maxwell/Videos/vlatestportfoliowebsite/.venv/lib/python3.13/site-packages/rest_framework/views.py", line 512, in dispatch
    response = handler(request, *args, **kwargs)
  File "/home/maxwell/Videos/vlatestportfoliowebsite/backend/django_portfolio/portfolio/views.py", line 149, in list
    print(f"Found {queryset.count()} projects")
                   ~~~~~~~~~~~~~~^^
  File "/home/maxwell/Videos/vlatestportfoliowebsite/.venv/lib/python3.13/site-packages/django/db/models/query.py", line 604, in count
    return self.query.get_count(using=self.db)
           ~~~~~~~~~~~~~~~~~~~~^^^^^^^^^^^^^^^
  File "/home/maxwell/Videos/vlatestportfoliowebsite/.venv/lib/python3.13/site-packages/django/db/models/sql/query.py", line 644, in get_count
    return obj.get_aggregation(using, {"__count": Count("*")})["__count"]
           ~~~~~~~~~~~~~~~~~~~^^^^^^^^^^^^^^^^^^^^^^^^^^^^^^^^
  File "/home/maxwell/Videos/vlatestportfoliowebsite/.venv/lib/python3.13/site-packages/django/db/models/sql/query.py", line 626, in get_aggregation
    result = compiler.execute_sql(SINGLE)
  File "/home/maxwell/Videos/vlatestportfoliowebsite/.venv/lib/python3.13/site-packages/django/db/models/sql/compiler.py", line 1623, in execute_sql
    cursor.execute(sql, params)
    ~~~~~~~~~~~~~~^^^^^^^^^^^^^
  File "/home/maxwell/Videos/vlatestportfoliowebsite/.venv/lib/python3.13/site-packages/django/db/backends/utils.py", line 122, in execute
    return super().execute(sql, params)
           ~~~~~~~~~~~~~~~^^^^^^^^^^^^^
  File "/home/maxwell/Videos/vlatestportfoliowebsite/.venv/lib/python3.13/site-packages/django/db/backends/utils.py", line 79, in execute
    return self._execute_with_wrappers(
           ~~~~~~~~~~~~~~~~~~~~~~~~~~~^
        sql, params, many=False, executor=self._execute
        ^^^^^^^^^^^^^^^^^^^^^^^^^^^^^^^^^^^^^^^^^^^^^^^
    )
    ^
  File "/home/maxwell/Videos/vlatestportfoliowebsite/.venv/lib/python3.13/site-packages/django/db/backends/utils.py", line 92, in _execute_with_wrappers
    return executor(sql, params, many, context)
  File "/home/maxwell/Videos/vlatestportfoliowebsite/.venv/lib/python3.13/site-packages/django/db/backends/utils.py", line 100, in _execute
    with self.db.wrap_database_errors:
         ^^^^^^^^^^^^^^^^^^^^^^^^^^^^
  File "/home/maxwell/Videos/vlatestportfoliowebsite/.venv/lib/python3.13/site-packages/django/db/utils.py", line 91, in __exit__
    raise dj_exc_value.with_traceback(traceback) from exc_value
  File "/home/maxwell/Videos/vlatestportfoliowebsite/.venv/lib/python3.13/site-packages/django/db/backends/utils.py", line 105, in _execute
    return self.cursor.execute(sql, params)
           ~~~~~~~~~~~~~~~~~~~^^^^^^^^^^^^^
  File "/home/maxwell/Videos/vlatestportfoliowebsite/.venv/lib/python3.13/site-packages/django/db/backends/sqlite3/base.py", line 360, in execute
    return super().execute(query, params)
           ~~~~~~~~~~~~~~~^^^^^^^^^^^^^^^
django.db.utils.OperationalError: no such table: portfolio_project
ERROR 2025-05-18 07:55:24,805 log 3900 139732189177536 Internal Server Error: /api/projects/
Traceback (most recent call last):
  File "/home/maxwell/Videos/vlatestportfoliowebsite/.venv/lib/python3.13/site-packages/django/db/backends/utils.py", line 105, in _execute
    return self.cursor.execute(sql, params)
           ~~~~~~~~~~~~~~~~~~~^^^^^^^^^^^^^
  File "/home/maxwell/Videos/vlatestportfoliowebsite/.venv/lib/python3.13/site-packages/django/db/backends/sqlite3/base.py", line 360, in execute
    return super().execute(query, params)
           ~~~~~~~~~~~~~~~^^^^^^^^^^^^^^^
sqlite3.OperationalError: no such table: portfolio_project

The above exception was the direct cause of the following exception:

Traceback (most recent call last):
  File "/home/maxwell/Videos/vlatestportfoliowebsite/.venv/lib/python3.13/site-packages/asgiref/sync.py", line 518, in thread_handler
    raise exc_info[1]
  File "/home/maxwell/Videos/vlatestportfoliowebsite/.venv/lib/python3.13/site-packages/django/core/handlers/exception.py", line 42, in inner
    response = await get_response(request)
               ^^^^^^^^^^^^^^^^^^^^^^^^^^^
  File "/home/maxwell/Videos/vlatestportfoliowebsite/.venv/lib/python3.13/site-packages/asgiref/sync.py", line 518, in thread_handler
    raise exc_info[1]
  File "/home/maxwell/Videos/vlatestportfoliowebsite/.venv/lib/python3.13/site-packages/django/core/handlers/base.py", line 253, in _get_response_async
    response = await wrapped_callback(
               ^^^^^^^^^^^^^^^^^^^^^^^
        request, *callback_args, **callback_kwargs
        ^^^^^^^^^^^^^^^^^^^^^^^^^^^^^^^^^^^^^^^^^^
    )
    ^
  File "/home/maxwell/Videos/vlatestportfoliowebsite/.venv/lib/python3.13/site-packages/asgiref/sync.py", line 468, in __call__
    ret = await asyncio.shield(exec_coro)
          ^^^^^^^^^^^^^^^^^^^^^^^^^^^^^^^
  File "/usr/local/lib/python3.13/concurrent/futures/thread.py", line 59, in run
    result = self.fn(*self.args, **self.kwargs)
  File "/home/maxwell/Videos/vlatestportfoliowebsite/.venv/lib/python3.13/site-packages/asgiref/sync.py", line 522, in thread_handler
    return func(*args, **kwargs)
  File "/home/maxwell/Videos/vlatestportfoliowebsite/.venv/lib/python3.13/site-packages/django/views/decorators/csrf.py", line 65, in _view_wrapper
    return view_func(request, *args, **kwargs)
  File "/home/maxwell/Videos/vlatestportfoliowebsite/.venv/lib/python3.13/site-packages/rest_framework/viewsets.py", line 125, in view
    return self.dispatch(request, *args, **kwargs)
           ~~~~~~~~~~~~~^^^^^^^^^^^^^^^^^^^^^^^^^^
  File "/home/maxwell/Videos/vlatestportfoliowebsite/.venv/lib/python3.13/site-packages/rest_framework/views.py", line 515, in dispatch
    response = self.handle_exception(exc)
  File "/home/maxwell/Videos/vlatestportfoliowebsite/.venv/lib/python3.13/site-packages/rest_framework/views.py", line 475, in handle_exception
    self.raise_uncaught_exception(exc)
    ~~~~~~~~~~~~~~~~~~~~~~~~~~~~~^^^^^
  File "/home/maxwell/Videos/vlatestportfoliowebsite/.venv/lib/python3.13/site-packages/rest_framework/views.py", line 486, in raise_uncaught_exception
    raise exc
  File "/home/maxwell/Videos/vlatestportfoliowebsite/.venv/lib/python3.13/site-packages/rest_framework/views.py", line 512, in dispatch
    response = handler(request, *args, **kwargs)
  File "/home/maxwell/Videos/vlatestportfoliowebsite/backend/django_portfolio/portfolio/views.py", line 149, in list
    print(f"Found {queryset.count()} projects")
                   ~~~~~~~~~~~~~~^^
  File "/home/maxwell/Videos/vlatestportfoliowebsite/.venv/lib/python3.13/site-packages/django/db/models/query.py", line 604, in count
    return self.query.get_count(using=self.db)
           ~~~~~~~~~~~~~~~~~~~~^^^^^^^^^^^^^^^
  File "/home/maxwell/Videos/vlatestportfoliowebsite/.venv/lib/python3.13/site-packages/django/db/models/sql/query.py", line 644, in get_count
    return obj.get_aggregation(using, {"__count": Count("*")})["__count"]
           ~~~~~~~~~~~~~~~~~~~^^^^^^^^^^^^^^^^^^^^^^^^^^^^^^^^
  File "/home/maxwell/Videos/vlatestportfoliowebsite/.venv/lib/python3.13/site-packages/django/db/models/sql/query.py", line 626, in get_aggregation
    result = compiler.execute_sql(SINGLE)
  File "/home/maxwell/Videos/vlatestportfoliowebsite/.venv/lib/python3.13/site-packages/django/db/models/sql/compiler.py", line 1623, in execute_sql
    cursor.execute(sql, params)
    ~~~~~~~~~~~~~~^^^^^^^^^^^^^
  File "/home/maxwell/Videos/vlatestportfoliowebsite/.venv/lib/python3.13/site-packages/django/db/backends/utils.py", line 122, in execute
    return super().execute(sql, params)
           ~~~~~~~~~~~~~~~^^^^^^^^^^^^^
  File "/home/maxwell/Videos/vlatestportfoliowebsite/.venv/lib/python3.13/site-packages/django/db/backends/utils.py", line 79, in execute
    return self._execute_with_wrappers(
           ~~~~~~~~~~~~~~~~~~~~~~~~~~~^
        sql, params, many=False, executor=self._execute
        ^^^^^^^^^^^^^^^^^^^^^^^^^^^^^^^^^^^^^^^^^^^^^^^
    )
    ^
  File "/home/maxwell/Videos/vlatestportfoliowebsite/.venv/lib/python3.13/site-packages/django/db/backends/utils.py", line 92, in _execute_with_wrappers
    return executor(sql, params, many, context)
  File "/home/maxwell/Videos/vlatestportfoliowebsite/.venv/lib/python3.13/site-packages/django/db/backends/utils.py", line 100, in _execute
    with self.db.wrap_database_errors:
         ^^^^^^^^^^^^^^^^^^^^^^^^^^^^
  File "/home/maxwell/Videos/vlatestportfoliowebsite/.venv/lib/python3.13/site-packages/django/db/utils.py", line 91, in __exit__
    raise dj_exc_value.with_traceback(traceback) from exc_value
  File "/home/maxwell/Videos/vlatestportfoliowebsite/.venv/lib/python3.13/site-packages/django/db/backends/utils.py", line 105, in _execute
    return self.cursor.execute(sql, params)
           ~~~~~~~~~~~~~~~~~~~^^^^^^^^^^^^^
  File "/home/maxwell/Videos/vlatestportfoliowebsite/.venv/lib/python3.13/site-packages/django/db/backends/sqlite3/base.py", line 360, in execute
    return super().execute(query, params)
           ~~~~~~~~~~~~~~~^^^^^^^^^^^^^^^
django.db.utils.OperationalError: no such table: portfolio_project
ERROR 2025-05-18 07:55:41,144 log 3900 139732197570240 Internal Server Error: /api/projects/
Traceback (most recent call last):
  File "/home/maxwell/Videos/vlatestportfoliowebsite/.venv/lib/python3.13/site-packages/django/db/backends/utils.py", line 105, in _execute
    return self.cursor.execute(sql, params)
           ~~~~~~~~~~~~~~~~~~~^^^^^^^^^^^^^
  File "/home/maxwell/Videos/vlatestportfoliowebsite/.venv/lib/python3.13/site-packages/django/db/backends/sqlite3/base.py", line 360, in execute
    return super().execute(query, params)
           ~~~~~~~~~~~~~~~^^^^^^^^^^^^^^^
sqlite3.OperationalError: no such table: portfolio_project

The above exception was the direct cause of the following exception:

Traceback (most recent call last):
  File "/home/maxwell/Videos/vlatestportfoliowebsite/.venv/lib/python3.13/site-packages/asgiref/sync.py", line 518, in thread_handler
    raise exc_info[1]
  File "/home/maxwell/Videos/vlatestportfoliowebsite/.venv/lib/python3.13/site-packages/django/core/handlers/exception.py", line 42, in inner
    response = await get_response(request)
               ^^^^^^^^^^^^^^^^^^^^^^^^^^^
  File "/home/maxwell/Videos/vlatestportfoliowebsite/.venv/lib/python3.13/site-packages/asgiref/sync.py", line 518, in thread_handler
    raise exc_info[1]
  File "/home/maxwell/Videos/vlatestportfoliowebsite/.venv/lib/python3.13/site-packages/django/core/handlers/base.py", line 253, in _get_response_async
    response = await wrapped_callback(
               ^^^^^^^^^^^^^^^^^^^^^^^
        request, *callback_args, **callback_kwargs
        ^^^^^^^^^^^^^^^^^^^^^^^^^^^^^^^^^^^^^^^^^^
    )
    ^
  File "/home/maxwell/Videos/vlatestportfoliowebsite/.venv/lib/python3.13/site-packages/asgiref/sync.py", line 468, in __call__
    ret = await asyncio.shield(exec_coro)
          ^^^^^^^^^^^^^^^^^^^^^^^^^^^^^^^
  File "/usr/local/lib/python3.13/concurrent/futures/thread.py", line 59, in run
    result = self.fn(*self.args, **self.kwargs)
  File "/home/maxwell/Videos/vlatestportfoliowebsite/.venv/lib/python3.13/site-packages/asgiref/sync.py", line 522, in thread_handler
    return func(*args, **kwargs)
  File "/home/maxwell/Videos/vlatestportfoliowebsite/.venv/lib/python3.13/site-packages/django/views/decorators/csrf.py", line 65, in _view_wrapper
    return view_func(request, *args, **kwargs)
  File "/home/maxwell/Videos/vlatestportfoliowebsite/.venv/lib/python3.13/site-packages/rest_framework/viewsets.py", line 125, in view
    return self.dispatch(request, *args, **kwargs)
           ~~~~~~~~~~~~~^^^^^^^^^^^^^^^^^^^^^^^^^^
  File "/home/maxwell/Videos/vlatestportfoliowebsite/.venv/lib/python3.13/site-packages/rest_framework/views.py", line 515, in dispatch
    response = self.handle_exception(exc)
  File "/home/maxwell/Videos/vlatestportfoliowebsite/.venv/lib/python3.13/site-packages/rest_framework/views.py", line 475, in handle_exception
    self.raise_uncaught_exception(exc)
    ~~~~~~~~~~~~~~~~~~~~~~~~~~~~~^^^^^
  File "/home/maxwell/Videos/vlatestportfoliowebsite/.venv/lib/python3.13/site-packages/rest_framework/views.py", line 486, in raise_uncaught_exception
    raise exc
  File "/home/maxwell/Videos/vlatestportfoliowebsite/.venv/lib/python3.13/site-packages/rest_framework/views.py", line 512, in dispatch
    response = handler(request, *args, **kwargs)
  File "/home/maxwell/Videos/vlatestportfoliowebsite/backend/django_portfolio/portfolio/views.py", line 149, in list
    print(f"Found {queryset.count()} projects")
                   ~~~~~~~~~~~~~~^^
  File "/home/maxwell/Videos/vlatestportfoliowebsite/.venv/lib/python3.13/site-packages/django/db/models/query.py", line 604, in count
    return self.query.get_count(using=self.db)
           ~~~~~~~~~~~~~~~~~~~~^^^^^^^^^^^^^^^
  File "/home/maxwell/Videos/vlatestportfoliowebsite/.venv/lib/python3.13/site-packages/django/db/models/sql/query.py", line 644, in get_count
    return obj.get_aggregation(using, {"__count": Count("*")})["__count"]
           ~~~~~~~~~~~~~~~~~~~^^^^^^^^^^^^^^^^^^^^^^^^^^^^^^^^
  File "/home/maxwell/Videos/vlatestportfoliowebsite/.venv/lib/python3.13/site-packages/django/db/models/sql/query.py", line 626, in get_aggregation
    result = compiler.execute_sql(SINGLE)
  File "/home/maxwell/Videos/vlatestportfoliowebsite/.venv/lib/python3.13/site-packages/django/db/models/sql/compiler.py", line 1623, in execute_sql
    cursor.execute(sql, params)
    ~~~~~~~~~~~~~~^^^^^^^^^^^^^
  File "/home/maxwell/Videos/vlatestportfoliowebsite/.venv/lib/python3.13/site-packages/django/db/backends/utils.py", line 122, in execute
    return super().execute(sql, params)
           ~~~~~~~~~~~~~~~^^^^^^^^^^^^^
  File "/home/maxwell/Videos/vlatestportfoliowebsite/.venv/lib/python3.13/site-packages/django/db/backends/utils.py", line 79, in execute
    return self._execute_with_wrappers(
           ~~~~~~~~~~~~~~~~~~~~~~~~~~~^
        sql, params, many=False, executor=self._execute
        ^^^^^^^^^^^^^^^^^^^^^^^^^^^^^^^^^^^^^^^^^^^^^^^
    )
    ^
  File "/home/maxwell/Videos/vlatestportfoliowebsite/.venv/lib/python3.13/site-packages/django/db/backends/utils.py", line 92, in _execute_with_wrappers
    return executor(sql, params, many, context)
  File "/home/maxwell/Videos/vlatestportfoliowebsite/.venv/lib/python3.13/site-packages/django/db/backends/utils.py", line 100, in _execute
    with self.db.wrap_database_errors:
         ^^^^^^^^^^^^^^^^^^^^^^^^^^^^
  File "/home/maxwell/Videos/vlatestportfoliowebsite/.venv/lib/python3.13/site-packages/django/db/utils.py", line 91, in __exit__
    raise dj_exc_value.with_traceback(traceback) from exc_value
  File "/home/maxwell/Videos/vlatestportfoliowebsite/.venv/lib/python3.13/site-packages/django/db/backends/utils.py", line 105, in _execute
    return self.cursor.execute(sql, params)
           ~~~~~~~~~~~~~~~~~~~^^^^^^^^^^^^^
  File "/home/maxwell/Videos/vlatestportfoliowebsite/.venv/lib/python3.13/site-packages/django/db/backends/sqlite3/base.py", line 360, in execute
    return super().execute(query, params)
           ~~~~~~~~~~~~~~~^^^^^^^^^^^^^^^
django.db.utils.OperationalError: no such table: portfolio_project
WARNING 2025-05-18 08:06:52,331 log 4842 140302907074240 Not Found: /api/project/3
